----------------------------------------------------------------------------------------------------
[INFO] - 2021-11-14 05:04:00,983

Source log file: /usr/lib/python3.9/site-packages/django/utils/autoreload.py line: 637

Watching for file changes with StatReloader
----------------------------------------------------------------------------------------------------
[WARNING] - 2021-11-14 05:05:11,093

Source log file: /usr/lib/python3.9/site-packages/django/utils/log.py line: 224

Not Found: /api/item/
----------------------------------------------------------------------------------------------------
[WARNING] - 2021-11-14 05:05:11,093

Source log file: /usr/lib/python3.9/site-packages/django/core/servers/basehttp.py line: 161

"GET /api/item/ HTTP/1.0" 404 2112
----------------------------------------------------------------------------------------------------
[INFO] - 2021-11-14 05:05:15,672

Source log file: /usr/lib/python3.9/site-packages/django/core/servers/basehttp.py line: 161

"GET /api/keystore HTTP/1.0" 301 0
----------------------------------------------------------------------------------------------------
[ERROR] - 2021-11-14 05:05:15,747

Source log file: /root/keystore/src/backend/keystore/views.py line: 25

Traceback (most recent call last):
  File "/usr/lib/python3.9/site-packages/django/db/backends/utils.py", line 84, in _execute
    return self.cursor.execute(sql, params)
psycopg2.errors.UndefinedTable: relation "K_KEYSTORE" does not exist
LINE 1: ...", "K_KEYSTORE"."memo", "K_KEYSTORE"."genre" FROM "K_KEYSTOR...
                                                             ^


The above exception was the direct cause of the following exception:

Traceback (most recent call last):
  File "/root/keystore/src/backend/keystore/views.py", line 22, in get
    response = serializers.serialize('json', query)
  File "/usr/lib/python3.9/site-packages/django/core/serializers/__init__.py", line 129, in serialize
    s.serialize(queryset, **options)
  File "/usr/lib/python3.9/site-packages/django/core/serializers/base.py", line 90, in serialize
    for count, obj in enumerate(queryset, start=1):
  File "/usr/lib/python3.9/site-packages/django/db/models/query.py", line 280, in __iter__
    self._fetch_all()
  File "/usr/lib/python3.9/site-packages/django/db/models/query.py", line 1324, in _fetch_all
    self._result_cache = list(self._iterable_class(self))
  File "/usr/lib/python3.9/site-packages/django/db/models/query.py", line 51, in __iter__
    results = compiler.execute_sql(chunked_fetch=self.chunked_fetch, chunk_size=self.chunk_size)
  File "/usr/lib/python3.9/site-packages/django/db/models/sql/compiler.py", line 1175, in execute_sql
    cursor.execute(sql, params)
  File "/usr/lib/python3.9/site-packages/django/db/backends/utils.py", line 98, in execute
    return super().execute(sql, params)
  File "/usr/lib/python3.9/site-packages/django/db/backends/utils.py", line 66, in execute
    return self._execute_with_wrappers(sql, params, many=False, executor=self._execute)
  File "/usr/lib/python3.9/site-packages/django/db/backends/utils.py", line 75, in _execute_with_wrappers
    return executor(sql, params, many, context)
  File "/usr/lib/python3.9/site-packages/django/db/backends/utils.py", line 84, in _execute
    return self.cursor.execute(sql, params)
  File "/usr/lib/python3.9/site-packages/django/db/utils.py", line 90, in __exit__
    raise dj_exc_value.with_traceback(traceback) from exc_value
  File "/usr/lib/python3.9/site-packages/django/db/backends/utils.py", line 84, in _execute
    return self.cursor.execute(sql, params)
django.db.utils.ProgrammingError: relation "K_KEYSTORE" does not exist
LINE 1: ...", "K_KEYSTORE"."memo", "K_KEYSTORE"."genre" FROM "K_KEYSTOR...
                                                             ^


----------------------------------------------------------------------------------------------------
[ERROR] - 2021-11-14 05:05:15,801

Source log file: /usr/lib/python3.9/site-packages/django/utils/log.py line: 224

Internal Server Error: /api/keystore/
Traceback (most recent call last):
  File "/usr/lib/python3.9/site-packages/django/db/backends/utils.py", line 84, in _execute
    return self.cursor.execute(sql, params)
psycopg2.errors.UndefinedTable: relation "K_KEYSTORE" does not exist
LINE 1: ...", "K_KEYSTORE"."memo", "K_KEYSTORE"."genre" FROM "K_KEYSTOR...
                                                             ^


The above exception was the direct cause of the following exception:

Traceback (most recent call last):
  File "/root/keystore/src/backend/keystore/views.py", line 22, in get
    response = serializers.serialize('json', query)
  File "/usr/lib/python3.9/site-packages/django/core/serializers/__init__.py", line 129, in serialize
    s.serialize(queryset, **options)
  File "/usr/lib/python3.9/site-packages/django/core/serializers/base.py", line 90, in serialize
    for count, obj in enumerate(queryset, start=1):
  File "/usr/lib/python3.9/site-packages/django/db/models/query.py", line 280, in __iter__
    self._fetch_all()
  File "/usr/lib/python3.9/site-packages/django/db/models/query.py", line 1324, in _fetch_all
    self._result_cache = list(self._iterable_class(self))
  File "/usr/lib/python3.9/site-packages/django/db/models/query.py", line 51, in __iter__
    results = compiler.execute_sql(chunked_fetch=self.chunked_fetch, chunk_size=self.chunk_size)
  File "/usr/lib/python3.9/site-packages/django/db/models/sql/compiler.py", line 1175, in execute_sql
    cursor.execute(sql, params)
  File "/usr/lib/python3.9/site-packages/django/db/backends/utils.py", line 98, in execute
    return super().execute(sql, params)
  File "/usr/lib/python3.9/site-packages/django/db/backends/utils.py", line 66, in execute
    return self._execute_with_wrappers(sql, params, many=False, executor=self._execute)
  File "/usr/lib/python3.9/site-packages/django/db/backends/utils.py", line 75, in _execute_with_wrappers
    return executor(sql, params, many, context)
  File "/usr/lib/python3.9/site-packages/django/db/backends/utils.py", line 84, in _execute
    return self.cursor.execute(sql, params)
  File "/usr/lib/python3.9/site-packages/django/db/utils.py", line 90, in __exit__
    raise dj_exc_value.with_traceback(traceback) from exc_value
  File "/usr/lib/python3.9/site-packages/django/db/backends/utils.py", line 84, in _execute
    return self.cursor.execute(sql, params)
django.db.utils.ProgrammingError: relation "K_KEYSTORE" does not exist
LINE 1: ...", "K_KEYSTORE"."memo", "K_KEYSTORE"."genre" FROM "K_KEYSTOR...
                                                             ^


During handling of the above exception, another exception occurred:

Traceback (most recent call last):
  File "/usr/lib/python3.9/site-packages/django/core/handlers/exception.py", line 47, in inner
    response = get_response(request)
  File "/usr/lib/python3.9/site-packages/django/core/handlers/base.py", line 181, in _get_response
    response = wrapped_callback(request, *callback_args, **callback_kwargs)
  File "/usr/lib/python3.9/site-packages/django/views/decorators/csrf.py", line 54, in wrapped_view
    return view_func(*args, **kwargs)
  File "/usr/lib/python3.9/site-packages/django/views/generic/base.py", line 70, in view
    return self.dispatch(request, *args, **kwargs)
  File "/usr/lib/python3.9/site-packages/rest_framework/views.py", line 509, in dispatch
    response = self.handle_exception(exc)
  File "/usr/lib/python3.9/site-packages/rest_framework/views.py", line 469, in handle_exception
    self.raise_uncaught_exception(exc)
  File "/usr/lib/python3.9/site-packages/rest_framework/views.py", line 480, in raise_uncaught_exception
    raise exc
  File "/usr/lib/python3.9/site-packages/rest_framework/views.py", line 506, in dispatch
    response = handler(request, *args, **kwargs)
  File "/root/keystore/src/backend/keystore/views.py", line 26, in get
    Response(serializer.errors, status=status.HTTP_500_INTERNAL_SERVER_ERROR)
NameError: name 'serializer' is not defined
----------------------------------------------------------------------------------------------------
[ERROR] - 2021-11-14 05:05:15,802

Source log file: /usr/lib/python3.9/site-packages/django/core/servers/basehttp.py line: 161

"GET /api/keystore/ HTTP/1.0" 500 152257
----------------------------------------------------------------------------------------------------
[INFO] - 2021-11-14 05:35:43,938

Source log file: /usr/lib/python3.9/site-packages/django/utils/autoreload.py line: 251

/root/keystore/src/backend/keystore/views.py changed, reloading.
----------------------------------------------------------------------------------------------------
[INFO] - 2021-11-14 05:35:44,293

Source log file: /usr/lib/python3.9/site-packages/django/utils/autoreload.py line: 637

Watching for file changes with StatReloader
----------------------------------------------------------------------------------------------------
[INFO] - 2021-11-14 05:36:35,318

Source log file: /usr/lib/python3.9/site-packages/django/utils/autoreload.py line: 251

/root/keystore/src/backend/keystore/views.py changed, reloading.
----------------------------------------------------------------------------------------------------
[INFO] - 2021-11-14 05:36:35,685

Source log file: /usr/lib/python3.9/site-packages/django/utils/autoreload.py line: 637

Watching for file changes with StatReloader
