----------------------------------------------------------------------------------------------------
[ERROR] - 2021-11-14 06:49:13,223

Source log file: /root/keystore/src/backend/keystore/views.py line: 25

Traceback (most recent call last):
  File "/usr/lib/python3.9/site-packages/django/db/backends/utils.py", line 84, in _execute
    return self.cursor.execute(sql, params)
psycopg2.errors.UndefinedColumn: column k_keystore.id does not exist
LINE 1: SELECT "k_keystore"."id", "k_keystore"."keyname", "k_keystor...
               ^


The above exception was the direct cause of the following exception:

Traceback (most recent call last):
  File "/root/keystore/src/backend/keystore/views.py", line 22, in get
    response = serializers.serialize('json', query)
  File "/usr/lib/python3.9/site-packages/django/core/serializers/__init__.py", line 129, in serialize
    s.serialize(queryset, **options)
  File "/usr/lib/python3.9/site-packages/django/core/serializers/base.py", line 90, in serialize
    for count, obj in enumerate(queryset, start=1):
  File "/usr/lib/python3.9/site-packages/django/db/models/query.py", line 280, in __iter__
    self._fetch_all()
  File "/usr/lib/python3.9/site-packages/django/db/models/query.py", line 1324, in _fetch_all
    self._result_cache = list(self._iterable_class(self))
  File "/usr/lib/python3.9/site-packages/django/db/models/query.py", line 51, in __iter__
    results = compiler.execute_sql(chunked_fetch=self.chunked_fetch, chunk_size=self.chunk_size)
  File "/usr/lib/python3.9/site-packages/django/db/models/sql/compiler.py", line 1175, in execute_sql
    cursor.execute(sql, params)
  File "/usr/lib/python3.9/site-packages/django/db/backends/utils.py", line 98, in execute
    return super().execute(sql, params)
  File "/usr/lib/python3.9/site-packages/django/db/backends/utils.py", line 66, in execute
    return self._execute_with_wrappers(sql, params, many=False, executor=self._execute)
  File "/usr/lib/python3.9/site-packages/django/db/backends/utils.py", line 75, in _execute_with_wrappers
    return executor(sql, params, many, context)
  File "/usr/lib/python3.9/site-packages/django/db/backends/utils.py", line 84, in _execute
    return self.cursor.execute(sql, params)
  File "/usr/lib/python3.9/site-packages/django/db/utils.py", line 90, in __exit__
    raise dj_exc_value.with_traceback(traceback) from exc_value
  File "/usr/lib/python3.9/site-packages/django/db/backends/utils.py", line 84, in _execute
    return self.cursor.execute(sql, params)
django.db.utils.ProgrammingError: column k_keystore.id does not exist
LINE 1: SELECT "k_keystore"."id", "k_keystore"."keyname", "k_keystor...
               ^


----------------------------------------------------------------------------------------------------
[ERROR] - 2021-11-14 06:49:13,224

Source log file: /usr/lib/python3.9/site-packages/django/utils/log.py line: 224

Internal Server Error: /api/keystore/
----------------------------------------------------------------------------------------------------
[ERROR] - 2021-11-14 06:49:13,224

Source log file: /usr/lib/python3.9/site-packages/django/core/servers/basehttp.py line: 161

"GET /api/keystore/ HTTP/1.0" 500 0
